<?xml version="1.0" encoding="UTF-8"?>
<!-- Generated by org.testng.reporters.JUnitReportReporter -->
<testsuite hostname="LAPTOP-K44KPQ32" failures="1" tests="4" name="com.qa.TestLayer.TestCaseForLogin" time="38.476" errors="0" timestamp="2022-08-04T16:46:40 IST" skipped="0">
  <testcase classname="com.qa.TestLayer.TestCaseForLogin" name="validUser_validPassword" time="10.259"/>
  <system-out/>
  <testcase classname="com.qa.TestLayer.TestCaseForLogin" name="validUser_InvalidPassword" time="5.173">
    <failure message="expected [https://www.saucedemo.com/] but found [https://www.saucedemo.com/inventory.html]" type="java.lang.AssertionError">
      <![CDATA[java.lang.AssertionError: expected [https://www.saucedemo.com/] but found [https://www.saucedemo.com/inventory.html]
at org.testng.Assert.fail(Assert.java:99)
at org.testng.Assert.failNotEquals(Assert.java:1037)
at org.testng.Assert.assertEqualsImpl(Assert.java:140)
at org.testng.Assert.assertEquals(Assert.java:122)
at org.testng.Assert.assertEquals(Assert.java:629)
at org.testng.Assert.assertEquals(Assert.java:639)
at com.qa.PageLayer.Login_swagLab.CheckTestCasestatus(Login_swagLab.java:40)
at com.qa.TestLayer.TestCaseForLogin.validUser_InvalidPassword(TestCaseForLogin.java:43)
at java.base/jdk.internal.reflect.DirectMethodHandleAccessor.invoke(DirectMethodHandleAccessor.java:104)
at java.base/java.lang.reflect.Method.invoke(Method.java:577)
at org.testng.internal.MethodInvocationHelper.invokeMethod(MethodInvocationHelper.java:133)
at org.testng.internal.TestInvoker.invokeMethod(TestInvoker.java:598)
at org.testng.internal.TestInvoker.invokeTestMethod(TestInvoker.java:173)
at org.testng.internal.MethodRunner.runInSequence(MethodRunner.java:46)
at org.testng.internal.TestInvoker$MethodInvocationAgent.invoke(TestInvoker.java:824)
at org.testng.internal.TestInvoker.invokeTestMethods(TestInvoker.java:146)
at org.testng.internal.TestMethodWorker.invokeTestMethods(TestMethodWorker.java:146)
at org.testng.internal.TestMethodWorker.run(TestMethodWorker.java:128)
at java.base/java.util.ArrayList.forEach(ArrayList.java:1511)
at org.testng.TestRunner.privateRun(TestRunner.java:794)
at org.testng.TestRunner.run(TestRunner.java:596)
at org.testng.SuiteRunner.runTest(SuiteRunner.java:377)
at org.testng.SuiteRunner.runSequentially(SuiteRunner.java:371)
at org.testng.SuiteRunner.privateRun(SuiteRunner.java:332)
at org.testng.SuiteRunner.run(SuiteRunner.java:276)
at org.testng.SuiteRunnerWorker.runSuite(SuiteRunnerWorker.java:53)
at org.testng.SuiteRunnerWorker.run(SuiteRunnerWorker.java:96)
at org.testng.TestNG.runSuitesSequentially(TestNG.java:1212)
at org.testng.TestNG.runSuitesLocally(TestNG.java:1134)
at org.testng.TestNG.runSuites(TestNG.java:1063)
at org.testng.TestNG.run(TestNG.java:1031)
at org.testng.remote.AbstractRemoteTestNG.run(AbstractRemoteTestNG.java:115)
at org.testng.remote.RemoteTestNG.initAndRun(RemoteTestNG.java:251)
at org.testng.remote.RemoteTestNG.main(RemoteTestNG.java:77)
]]>
    </failure>
  </testcase> <!-- validUser_InvalidPassword -->
  <system-out/>
  <testcase classname="com.qa.TestLayer.TestCaseForLogin" name="InvalidUser_validPassword" time="13.174"/>
  <system-out/>
  <testcase classname="com.qa.TestLayer.TestCaseForLogin" name="InvalidUser_InvalidPassword" time="9.870"/>
  <system-out/>
</testsuite> <!-- com.qa.TestLayer.TestCaseForLogin -->
